Workbook

Sheet README
C3: Notas importantes
B5: 1 | C5: Llenar por favor TODAS las hojas y los espacios en blanco de este libro de Excel.
B6: 2 | C6: Acompañe los datos de las casillas con comentarios para facilitar la comprensión de los datos, su origen, los cálculos, los supuestos, entre otros.
B7: 3 | C7: Si requiere agregar más hojas, más filas o columnas, más tecnologías u otro para completar todos los datos necesarios de los 3 escenarios complementarios al BAU, hágalo por favor.
B8: 4 | C8: Agregue comentarios explicativos bajo las tablas de los datos para la mejor comprensión de los escenarios.
B9: 5 | C9: Si tiene dudas, contacte a los equipos o personas correspondientes para aclararlas.
B10: 6 | C10: Si las variables dentro de las hojas no varían en comparación con el escenario BAU, replicar los datos donde corresponda e indicar que esto pasa.
B11: 7 | C11: Siempre que sea posible, acompañe los datos con la referencia de procedencia (enlaces de la web, nombre del informe u otro).
B12: 8 | C12: No se detallan necesariamente todas las tecnologías. Se incorporaron algunas de ellas y es cuestión de agregar más líneas para caracterizar cada tecnología, sobretodo con las tecnologías reductoras de emisiones o indicadores mejorados de los 3 escenarios de emisiones reducidas.
B13: 9 | C13: En algunos casos, se incluyeros unidades predeterminadas para los datos. Si los datos están en otras unidades o es mejor verlos en otras unidades, modifíquelo por favor.
B14: 10 | C14: Si solo se tienen valores en años puntuales o años meta y no en todo el intervalo, colóquelos en el año correspondiente de igual manera. Se usará algún método de interpolación o extrapolación para completar todo el intervalo.
B15: 11 | C15: Si existen datos de la recuperación de metano consumido para generación de electricidad con plantas instaladas en vertederos, crear una nueva hoja e indicar la evolución esperada en el tiempo de esa tecnología.

Sheet ProduccionResiduosSolidos
C1: Ecuador | D1: 2010 | E1: 2011 | F1: 2012 | G1: 2013 | H1: 2014 | I1: 2015 | J1: 2016 | K1: 2017 | L1: 2018 | M1: 2019 | N1: 2020 | O1: 2021 | P1: 2022 | Q1: 2023 | R1: 2024 | S1: 2025 | T1: 2026 | U1: 2027 | V1: 2028 | W1: 2029 | X1: 2030 | Y1: 2031 | Z1: 2032 | AA1: 2033 | AB1: 2034 | AC1: 2035
C4: RESIDUOS SÓLIDOS
C5: Población INEN | D5: 14883661 | E5: 15160587 | F5: 15440550 | G5: 15717514 | H5: 15994366 | I5: 16269171 | J5: 16532265 | K5: 16792803 | L5: 17023408 | M5: 17267986 | N5: 17510643 | O5: 17751277 | P5: 17989912 | Q5: 18226512 | R5: 17966573 | S5: 18103660 | T5: 18243816 | U5: 18385975 | V5: 18529121 | W5: 18672456 | X5: 18815497 | Y5: 18957924 | Z5: 19099478 | AA5: 19239759 | AB5: 19378452 | AC5: 19515303
C6: Fuente: INEC 2024. https://www.ecuadorencifras.gob.ec/proyecciones-poblacionales/
C8: Producción per cápita PPC [kg residuos sólidos/año]
C9: Tendencial Nacional | D9: 0.74868269 | E9: 0.76193328 | F9: 0.77153461 | G9: 0.8651815 | H9: 0.96349654 | I9: 0.89204956 | J9: 0.83803574 | K9: 0.82253337 | L9: 0.80888483 | M9: 0.79910816 | N9: 0.83 | O9: 0.78 | P9: 0.83779624 | Q9: 0.8803189 | R9: 0.9225226 | S9: 0.96463385 | T9: 1.0067584 | U9: 1.0488757 | V9: 1.0910322 | W9: 1.1332685 | X9: 1.1755241 | Y9: 1.1894809 | Z9: 1.2033134 | AA9: 1.2170086 | AB9: 1.2306063 | AC9: 1.2441141
C10: Fuente: Base de datos PLAN MICC y 2NDC
C11: Producción de residuos sólidos [Mt]
C12: Tendencial Nacional | D12: =(D9*D5*365)/1000000000 -> 4.0672459 | E12: =(E9*E5*365)/1000000000 -> 4.2162448 | F12: =(F9*F5*365)/1000000000 -> 4.3482153 | G12: =(G9*G5*365)/1000000000 -> 4.9634533 | H12: =(H9*H5*365)/1000000000 -> 5.6248384 | I12: =(I9*I5*365)/1000000000 -> 5.297211 | J12: =(J9*J5*365)/1000000000 -> 5.0569395 | K12: =(K9*K5*365)/1000000000 -> 5.0416139 | ... AC12: =(AC9*AC5*365)/1000000000 -> 8.8619312

Sheet ParticipacionTechsSolidosBA (2)
D1: Ecuador | E1: 2010 | F1: 2011 | G1: 2012 | H1: 2013 | I1: 2014 | J1: 2015 | K1: 2016 | L1: 2017 | M1: 2018 | N1: 2019 | O1: 2020 | P1: 2021 | Q1: 2022 | R1: 2023 | S1: 2024 | T1: 2025 | U1: 2026 | V1: 2027 | W1: 2028 | X1: 2029 | Y1: 2030 | Z1: 2031 | AA1: 2032 | AB1: 2033 | AC1: 2034 | AD1: 2035 | AE1: 2036 | AF1: 2037 | AG1: 2038 | AH1: 2039 | AI1: 2040 | AJ1: 2041 | AK1: 2042 | AL1: 2043 | AM1: 2044 | AN1: 2045 | AO1: 2046 | AP1: 2047 | AQ1: 2048 | AR1: 2049 | AS1: 2050 | AT1: 2051 | AU1: 2052 | AV1: 2053 | AW1: 2054 | AX1: 2055 | AY1: 2056 | AZ1: 2057 | BA1: 2058 | BB1: 2059 | BC1: 2060 | BD1: 2061 | BE1: 2062 | BF1: 2063 | BG1: 2064 | BH1: 2065 | BI1: 2066 | BJ1: 2067 | BK1: 2068 | BL1: 2069 | BM1: 2070
D4: Residuos sólidos (PORCENTAJES)
C6: Códificación OSeMOSYS | D6: BAU
C8: Etapa 4: Disposición final
C9: INORG_RCY_OS | D9: Inorgánicos u otros sin emisiones | E9: =1-E10-E11-E12-E13-E14-E15-E16-E17-E18 -> 0.41274758 | F9: =1-F10-F11-F12-F13-F14-F15-F16-F17-F18 -> 0.41274758 | G9: =1-G10-G11-G12-G13-G14-G15-G16-G17-G18 -> 0.41274758 | H9: =1-H10-H11-H12-H13-H14-H15-H16-H17-H18 -> 0.41274758 | I9: =1-I10-I11-I12-I13-I14-I15-I16-I17-I18 -> 0.41274758 | J9: =1-J10-J11-J12-J13-J14-J15-J16-J17-J18 -> 0.41178481 | K9: =1-K10-K11-K12-K13-K14-K15-K16-K17-K18 -> 0.40541367 | L9: =1-L10-L11-L12-L13-L14-L15-L16-L17-L18 -> 0.39926298 | ... BM9: =1-BM10-BM11-BM12-BM13-BM14-BM15-BM16-BM17-BM18 -> 0.35701225
C10: AD | D10: Digestión Anaerobica | E10: 0 | F10: 0 | G10: 0 | H10: 0 | I10: 0 | J10: 0 | K10: 0 | L10: 0 | M10: 0 | N10: 0 | O10: 0 | P10: 0 | Q10: 0 | R10: 0 | S10: 0 | T10: 0 | U10: 0 | V10: 0 | W10: 0 | X10: 0 | Y10: 0 | Z10: 0 | AA10: 0 | AB10: 0 | AC10: 0 | AD10: 0 | AE10: 0 | AF10: 0 | AG10: 0 | AH10: 0 | AI10: 0 | AJ10: 0 | AK10: 0 | AL10: 0 | AM10: 0 | AN10: 0 | AO10: 0 | AP10: 0 | AQ10: 0 | AR10: 0 | AS10: 0 | AT10: 0 | AU10: 0 | AV10: 0 | AW10: 0 | AX10: 0 | AY10: 0 | AZ10: 0 | BA10: 0 | BB10: 0 | BC10: 0 | BD10: 0 | BE10: 0 | BF10: 0 | BG10: 0 | BH10: 0 | BI10: 0 | BJ10: 0 | BK10: 0 | BL10: 0 | BM10: 0
C11: COMPOST | D11: Compostaje | E11: =E44/E83 -> 0.0013522664 | F11: =F44/F83 -> 0.0015179384 | G11: =G44/G83 -> 0.0016788497 | H11: =H44/H83 -> 0.0044726924 | I11: =I44/I83 -> 0.0066135233 | J11: =J44/J83 -> 0.0060786705 | K11: =K44/K83 -> 0.0053787473 | L11: =L44/L83 -> 0.0060496501 | ... AD11: =AD44/AD83 -> 0.0066828611 | AE11: 0.0066828611 | AF11: 0.0066828611 | AG11: 0.0066828611 | AH11: 0.0066828611 | AI11: 0.0066828611 | AJ11: 0.0066828611 | AK11: 0.0066828611 | AL11: 0.0066828611 | AM11: 0.0066828611 | AN11: 0.0066828611 | AO11: 0.0066828611 | AP11: 0.0066828611 | AQ11: 0.0066828611 | AR11: 0.0066828611 | AS11: 0.0066828611 | AT11: 0.0066828611 | AU11: 0.0066828611 | AV11: 0.0066828611 | AW11: 0.0066828611 | AX11: 0.0066828611 | AY11: 0.0066828611 | AZ11: 0.0066828611 | BA11: 0.0066828611 | BB11: 0.0066828611 | BC11: 0.0066828611 | BD11: 0.0066828611 | BE11: 0.0066828611 | BF11: 0.0066828611 | BG11: 0.0066828611 | BH11: 0.0066828611 | BI11: 0.0066828611 | BJ11: 0.0066828611 | BK11: 0.0066828611 | BL11: 0.0066828611 | BM11: 0.0066828611
C12: LANDFILL_BG | D12: Relleno sanitario con quema biogas | E12: 0 | F12: 0 | G12: 0 | H12: 0 | I12: 0 | J12: 0 | K12: 0.00733391 | L12: 0.012651526 | M12: 0.012651526 | N12: 0.012651526 | O12: 0.012651526 | P12: 0.012651526 | Q12: 0.012651526 | R12: 0.012651526 | S12: 0.012651526 | T12: 0.012651526 | U12: 0.012651526 | V12: 0.012651526 | W12: 0.012651526 | X12: 0.012651526 | Y12: 0.012651526 | Z12: 0.012651526 | AA12: 0.012651526 | AB12: 0.012651526 | AC12: 0.012651526 | AD12: 0.012651526 | AE12: 0.012651526 | AF12: 0.012651526 | AG12: 0.012651526 | AH12: 0.012651526 | AI12: 0.012651526 | AJ12: 0.012651526 | AK12: 0.012651526 | AL12: 0.012651526 | AM12: 0.012651526 | AN12: 0.012651526 | AO12: 0.012651526 | AP12: 0.012651526 | AQ12: 0.012651526 | AR12: 0.012651526 | AS12: 0.012651526 | AT12: 0.012651526 | AU12: 0.012651526 | AV12: 0.012651526 | AW12: 0.012651526 | AX12: 0.012651526 | AY12: 0.012651526 | AZ12: 0.012651526 | BA12: 0.012651526 | BB12: 0.012651526 | BC12: 0.012651526 | BD12: 0.012651526 | BE12: 0.012651526 | BF12: 0.012651526 | BG12: 0.012651526 | BH12: 0.012651526 | BI12: 0.012651526 | BJ12: 0.012651526 | BK12: 0.012651526 | BL12: 0.012651526 | BM12: 0.012651526
C13: LANDFILL | D13: Sitios gestionados | E13: =E45/E83 -> 0.30664485 | F13: =F45/F83 -> 0.32113885 | G13: =G45/G83 -> 0.33305618 | H13: =H45/H83 -> 0.3172388 | I13: =I45/I83 -> 0.30415096 | J13: =J45/J83 -> 0.3769342 | K13: =K45/K83 -> 0.4386052 | L13: =L45/L83 -> 0.46566438 | ... AD13: =AD45/AD83 -> 0.54545973 | AE13: 0.54545973 | AF13: 0.54545973 | AG13: 0.54545973 | AH13: 0.54545973 | AI13: 0.54545973 | AJ13: 0.54545973 | AK13: 0.54545973 | AL13: 0.54545973 | AM13: 0.54545973 | AN13: 0.54545973 | AO13: 0.54545973 | AP13: 0.54545973 | AQ13: 0.54545973 | AR13: 0.54545973 | AS13: 0.54545973 | AT13: 0.54545973 | AU13: 0.54545973 | AV13: 0.54545973 | AW13: 0.54545973 | AX13: 0.54545973 | AY13: 0.54545973 | AZ13: 0.54545973 | BA13: 0.54545973 | BB13: 0.54545973 | BC13: 0.54545973 | BD13: 0.54545973 | BE13: 0.54545973 | BF13: 0.54545973 | BG13: 0.54545973 | BH13: 0.54545973 | BI13: 0.54545973 | BJ13: 0.54545973 | BK13: 0.54545973 | BL13: 0.54545973 | BM13: 0.54545973
C14: NO_CONTR_OD | D14: Sitios no gestionados | E14: =E46/E83 -> 0.27701792 | F14: =F46/F83 -> 0.26229501 | G14: =G46/G83 -> 0.25012561 | H14: =H46/H83 -> 0.26336502 | I14: =I46/I83 -> 0.274479 | J14: =J46/J83 -> 0.203088 | K14: =K46/K83 -> 0.14105369 | L14: =L46/L83 -> 0.11411028 | ... AD14: =AD46/AD83 -> 0.076325309 | AE14: 0.076325309 | AF14: 0.076325309 | AG14: 0.076325309 | AH14: 0.076325309 | AI14: 0.076325309 | AJ14: 0.076325309 | AK14: 0.076325309 | AL14: 0.076325309 | AM14: 0.076325309 | AN14: 0.076325309 | AO14: 0.076325309 | AP14: 0.076325309 | AQ14: 0.076325309 | AR14: 0.076325309 | AS14: 0.076325309 | AT14: 0.076325309 | AU14: 0.076325309 | AV14: 0.076325309 | AW14: 0.076325309 | AX14: 0.076325309 | AY14: 0.076325309 | AZ14: 0.076325309 | BA14: 0.076325309 | BB14: 0.076325309 | BC14: 0.076325309 | BD14: 0.076325309 | BE14: 0.076325309 | BF14: 0.076325309 | BG14: 0.076325309 | BH14: 0.076325309 | BI14: 0.076325309 | BJ14: 0.076325309 | BK14: 0.076325309 | BL14: 0.076325309 | BM14: 0.076325309
C15: COPROC | D15: Coprocesamiento | E15: 0 | F15: 0 | G15: 0 | H15: 0 | I15: 0 | J15: 0 | K15: 0 | L15: 0 | M15: 0 | N15: 0 | O15: 0 | P15: 0 | Q15: 0 | R15: 0 | S15: 0 | T15: 0 | U15: 0 | V15: 0 | W15: 0 | X15: 0 | Y15: 0 | Z15: 0 | AA15: 0 | AB15: 0 | AC15: 0 | AD15: 0 | AE15: 0 | AF15: 0 | AG15: 0 | AH15: 0 | AI15: 0 | AJ15: 0 | AK15: 0 | AL15: 0 | AM15: 0 | AN15: 0 | AO15: 0 | AP15: 0 | AQ15: 0 | AR15: 0 | AS15: 0 | AT15: 0 | AU15: 0 | AV15: 0 | AW15: 0 | AX15: 0 | AY15: 0 | AZ15: 0 | BA15: 0 | BB15: 0 | BC15: 0 | BD15: 0 | BE15: 0 | BF15: 0 | BG15: 0 | BH15: 0 | BI15: 0 | BJ15: 0 | BK15: 0 | BL15: 0 | BM15: 0
C16: INCIN | D16: Incineranción contralada | E16: =E47/E83 -> 0.0022373862 | F16: =F47/F83 -> 0.0023006254 | G16: =G47/G83 -> 0.0023917859 | H16: =H47/H83 -> 0.0021759044 | I16: =I47/I83 -> 0.0020089466 | J16: =J47/J83 -> 0.0021143202 | K16: =K47/K83 -> 0.0022147783 | L16: =L47/L83 -> 0.0022611807 | ... BM16: =BM47/BM83 -> 0.001868321
C17: OPEN_BURN | D17: Quema a cielo abierto | E17: 0 | F17: 0 | G17: 0 | H17: 0 | I17: 0 | J17: 0 | K17: 0 | L17: 0 | M17: 0 | N17: 0 | O17: 0 | P17: 0 | Q17: 0 | R17: 0 | S17: 0 | T17: 0 | U17: 0 | V17: 0 | W17: 0 | X17: 0 | Y17: 0 | Z17: 0 | AA17: 0 | AB17: 0 | AC17: 0 | AD17: 0 | AE17: 0 | AF17: 0 | AG17: 0 | AH17: 0 | AI17: 0 | AJ17: 0 | AK17: 0 | AL17: 0 | AM17: 0 | AN17: 0 | AO17: 0 | AP17: 0 | AQ17: 0 | AR17: 0 | AS17: 0 | AT17: 0 | AU17: 0 | AV17: 0 | AW17: 0 | AX17: 0 | AY17: 0 | AZ17: 0 | BA17: 0 | BB17: 0 | BC17: 0 | BD17: 0 | BE17: 0 | BF17: 0 | BG17: 0 | BH17: 0 | BI17: 0 | BJ17: 0 | BK17: 0 | BL17: 0 | BM17: 0
C18: SIT_CLAN | D18: Disposición en sitios clandestinos | E18: 0 | F18: 0 | G18: 0 | H18: 0 | I18: 0 | J18: 0 | K18: 0 | L18: 0 | M18: 0 | N18: 0 | O18: 0 | P18: 0 | Q18: 0 | R18: 0 | S18: 0 | T18: 0 | U18: 0 | V18: 0 | W18: 0 | X18: 0 | Y18: 0 | Z18: 0 | AA18: 0 | AB18: 0 | AC18: 0 | AD18: 0 | AE18: 0 | AF18: 0 | AG18: 0 | AH18: 0 | AI18: 0 | AJ18: 0 | AK18: 0 | AL18: 0 | AM18: 0 | AN18: 0 | AO18: 0 | AP18: 0 | AQ18: 0 | AR18: 0 | AS18: 0 | AT18: 0 | AU18: 0 | AV18: 0 | AW18: 0 | AX18: 0 | AY18: 0 | AZ18: 0 | BA18: 0 | BB18: 0 | BC18: 0 | BD18: 0 | BE18: 0 | BF18: 0 | BG18: 0 | BH18: 0 | BI18: 0 | BJ18: 0 | BK18: 0 | BL18: 0 | BM18: 0
E19: =SUM(E9:E18) -> 1 | F19: =SUM(F9:F18) -> 1 | G19: =SUM(G9:G18) -> 1 | H19: =SUM(H9:H18) -> 1 | I19: =SUM(I9:I18) -> 1 | J19: =SUM(J9:J18) -> 1 | K19: =SUM(K9:K18) -> 1 | L19: =SUM(L9:L18) -> 1 | ... BM19: =SUM(BM9:BM18) -> 1
D21: Relleno sanitario | E21: 0.15345822 | F21: 0.17844801 | G21: 0.18257969 | H21: 0.2533691 | I21: 0.29152718 | J21: 0.31758447 | K21: 0.34105926 | L21: 0.28420064 | M21: 0.29868552 | N21: 0.30029408 | O21: 0.33361839 | P21: 0.42025908 | Q21: 0.46132695 | R21: 0.51146955 | S21: 0.52365633
D22: Reciclaje de residuos inorgánicos separados en sitio de disposición final | E22: 0.024154045 | F22: 0.025147903 | G22: 0.025940634 | H22: 0.028244366 | I22: 0.027714 | J22: 0.02772 | K22: 0.027354 | L22: 0.038622 | M22: 0.0402084 | N22: 0.037584 | O22: 0.0382752 | P22: 0.0385392 | Q22: 0.04021848 | R22: 0.0423756 | S22: 0.0423756 | T22: 0.04091826 | U22: 0.039460921 | V22: 0.038003581 | W22: 0.036546241 | X22: 0.035088902 | Y22: 0.033631562 | Z22: 0.03368361 | AA22: 0.033735658 | AB22: 0.033787705 | AC22: 0.033839753 | AD22: 0.033891801 | AE22: 0.033943849 | AF22: 0.033995897 | AG22: 0.034047945 | AH22: 0.034099992 | AI22: 0.03415204 | AJ22: 0.034204088 | AK22: 0.034256136 | AL22: 0.034308184 | AM22: 0.034360232 | AN22: 0.03441228 | AO22: 0.034464327 | AP22: 0.034516375 | AQ22: 0.034568423 | AR22: 0.034620471 | AS22: 0.034672519 | AT22: 0.034672519 | AU22: 0.034672519 | AV22: 0.034672519 | AW22: 0.034672519 | AX22: 0.034672519 | AY22: 0.034672519 | AZ22: 0.034672519 | BA22: 0.034672519 | BB22: 0.034672519 | BC22: 0.034672519 | BD22: 0.034672519 | BE22: 0.034672519 | BF22: 0.034672519 | BG22: 0.034672519 | BH22: 0.034672519 | BI22: 0.034672519 | BJ22: 0.034672519 | BK22: 0.034672519 | BL22: 0.034672519 | BM22: 0.034507701
C24: Etapa 3: Separación en el sitio de disposición final
C25: OSS_INORG | D25: Separación de residuos inorgánicos en sitio de disposición final | E25: 0.024154045 | F25: 0.025147903 | G25: 0.025940634 | H25: 0.028244366 | I25: 0.027714 | J25: 0.02772 | K25: 0.027354 | L25: 0.038622 | M25: 0.0402084 | N25: 0.037584 | O25: 0.0382752 | P25: 0.0385392 | Q25: 0.04021848 | R25: 0.0423756 | S25: 0.0423756 | T25: =$H$92+$H$91*T1 -> 0.04091826 | U25: =$H$92+$H$91*U1 -> 0.039460921 | V25: =$H$92+$H$91*V1 -> 0.038003581 | W25: =$H$92+$H$91*W1 -> 0.036546241 | X25: =$H$92+$H$91*X1 -> 0.035088902 | Y25: =AVERAGE(E25:S25) -> 0.033631562 | Z25: =$I$92+$I$91*Z1 -> 0.03368361 | AA25: =$I$92+$I$91*AA1 -> 0.033735658 | AB25: =$I$92+$I$91*AB1 -> 0.033787705 | AC25: =$I$92+$I$91*AC1 -> 0.033839753 | AD25: =$I$92+$I$91*AD1 -> 0.033891801 | AE25: =$I$92+$I$91*AE1 -> 0.033943849 | AF25: =$I$92+$I$91*AF1 -> 0.033995897 | AG25: =$I$92+$I$91*AG1 -> 0.034047945 | ... AR25: =$I$92+$I$91*AR1 -> 0.034620471 | AS25: =AVERAGE(E25:Y25) -> 0.034672519 | AT25: 0.034672519 | AU25: 0.034672519 | AV25: 0.034672519 | AW25: 0.034672519 | AX25: 0.034672519 | AY25: 0.034672519 | AZ25: 0.034672519 | BA25: 0.034672519 | BB25: 0.034672519 | BC25: 0.034672519 | BD25: 0.034672519 | BE25: 0.034672519 | BF25: 0.034672519 | BG25: 0.034672519 | BH25: 0.034672519 | BI25: 0.034672519 | BJ25: 0.034672519 | BK25: 0.034672519 | BL25: 0.034672519 | BM25: =AVERAGE(E25:BL25) -> 0.034507701
C26: OSS_ORG | D26: Separación de residuos orgánicos en sitio de disposición final | E26: 0.023762538 | F26: 0.025779778 | G26: 0.027964623 | H26: 0.028890301 | I26: 0.026905 | J26: 0.0319 | K26: 0.025705 | L26: 0.044745 | M26: 0.042993 | N26: 0.04068 | O26: 0.040104 | P26: 0.041884 | Q26: 0.0494846 | R26: 0.043687 | S26: 0.043687 | T26: =$H$94+$H$93*T1 -> 0.04238552 | U26: =$H$94+$H$93*U1 -> 0.041084041 | V26: =$H$94+$H$93*V1 -> 0.039782561 | W26: =$H$94+$H$93*W1 -> 0.038481082 | X26: =$H$94+$H$93*X1 -> 0.037179602 | Y26: =AVERAGE(E26:S26) -> 0.035878123 | Z26: =$I$94+$I$93*Z1 -> 0.035924604 | AA26: =$I$94+$I$93*AA1 -> 0.035971086 | AB26: =$I$94+$I$93*AB1 -> 0.036017567 | AC26: =$I$94+$I$93*AC1 -> 0.036064048 | AD26: =$I$94+$I$93*AD1 -> 0.03611053 | AE26: =$I$94+$I$93*AE1 -> 0.036157011 | AF26: =$I$94+$I$93*AF1 -> 0.036203493 | AG26: =$I$94+$I$93*AG1 -> 0.036249974 | ... AR26: =$I$94+$I$93*AR1 -> 0.03676127 | AS26: =AVERAGE(E26:Y26) -> 0.036807751 | AT26: 0.036807751 | AU26: 0.036807751 | AV26: 0.036807751 | AW26: 0.036807751 | AX26: 0.036807751 | AY26: 0.036807751 | AZ26: 0.036807751 | BA26: 0.036807751 | BB26: 0.036807751 | BC26: 0.036807751 | BD26: 0.036807751 | BE26: 0.036807751 | BF26: 0.036807751 | BG26: 0.036807751 | BH26: 0.036807751 | BI26: 0.036807751 | BJ26: 0.036807751 | BK26: 0.036807751 | BL26: 0.036807751 | BM26: =AVERAGE(E26:BL26) -> 0.03666056
C27: NO_OSS_BLEND | D27: No separación de residuos mezclados en sitio de disposición final | E27: 0.95208342 | F27: 0.94907232 | G27: 0.94609474 | H27: 0.94286533 | I27: 0.945381 | J27: 0.94038 | K27: 0.946941 | L27: 0.896633 | M27: 0.9167986 | N27: 0.921736 | O27: 0.9216208 | P27: 0.9195768 | Q27: 0.91029692 | R27: 0.9139374 | S27: 0.91847658 | T27: =1-T26-T25 -> 0.91669622 | U27: =1-U26-U25 -> 0.91945504 | V27: =1-V26-V25 -> 0.92221386 | W27: =1-W26-W25 -> 0.92497268 | X27: =1-X26-X25 -> 0.9277315 | Y27: =1-Y26-Y25 -> 0.93049032 | Z27: =1-Z26-Z25 -> 0.93039179 | AA27: =1-AA26-AA25 -> 0.93029326 | ... BM27: =1-BM26-BM25 -> 0.92883174
C28: NO_OSS_NO_COLL | D28: No separación de residuos mezclados no recolectados | E28: 0.0022373862 | F28: 0.0022373862 | G28: 0.0022373862 | H28: 0.0022373862 | I28: 0.0022373862 | J28: 0.0022373862 | K28: 0.0022373862 | L28: 0.0022373862 | M28: 0.0022373862 | N28: 0.0022373862 | O28: 0.0022373862 | P28: 0.0022373862 | Q28: 0.0022373862 | R28: 0.0022373862 | S28: 0.0022373862 | T28: 0.0022373862 | U28: 0.0022373862 | V28: 0.0022373862 | W28: 0.0022373862 | X28: 0.0022373862 | Y28: 0.0022373862 | Z28: 0.0022373862 | AA28: 0.0022373862 | AB28: 0.0022373862 | AC28: 0.0022373862 | AD28: 0.0022373862 | AE28: 0.0022373862 | AF28: 0.0022373862 | AG28: 0.0022373862 | AH28: 0.0022373862 | AI28: 0.0022373862 | AJ28: 0.0022373862 | AK28: 0.0022373862 | AL28: 0.0022373862 | AM28: 0.0022373862 | AN28: 0.0022373862 | AO28: 0.0022373862 | AP28: 0.0022373862 | AQ28: 0.0022373862 | AR28: 0.0022373862 | AS28: 0.0022373862 | AT28: 0.0022373862 | AU28: 0.0022373862 | AV28: 0.0022373862 | AW28: 0.0022373862 | AX28: 0.0022373862 | AY28: 0.0022373862 | AZ28: 0.0022373862 | BA28: 0.0022373862 | BB28: 0.0022373862 | BC28: 0.0022373862 | BD28: 0.0022373862 | BE28: 0.0022373862 | BF28: 0.0022373862 | BG28: 0.0022373862 | BH28: 0.0022373862 | BI28: 0.0022373862 | BJ28: 0.0022373862 | BK28: 0.0022373862 | BL28: 0.0022373862 | BM28: 0.0022373862
E29: =E25+E26+E27 -> 1 | F29: =F25+F26+F27 -> 1 | G29: =G25+G26+G27 -> 1 | H29: =H25+H26+H27 -> 1 | I29: =I25+I26+I27 -> 1 | J29: =J25+J26+J27 -> 1 | K29: =K25+K26+K27 -> 1 | L29: =L25+L26+L27 -> 0.98 | ... BM29: =BM25+BM26+BM27 -> 1
C30: Etapa 2: Recolección
C31: INORG_DCOLL | D31: Recolección diferenciada de residuos inorgánicos | E31: 0.047525076 | F31: 0.051559556 | G31: 0.055929246 | H31: 0.057780602 | I31: 0.05381 | J31: 0.0638 | K31: 0.05141 | L31: 0.08949 | M31: 0.085986 | N31: 0.08136 | O31: 0.080208 | P31: 0.083768 | Q31: 0.0989692 | R31: 0.087374 | S31: 0.087374 | T31: 0.087374 | U31: 0.087374 | V31: 0.087374 | W31: 0.087374 | X31: 0.087374 | Y31: 0.087374 | Z31: 0.087374 | AA31: 0.087374 | AB31: 0.087374 | AC31: 0.087374 | AD31: 0.087374 | AE31: 0.087374 | AF31: 0.087374 | AG31: 0.087374 | AH31: 0.087374 | AI31: 0.087374 | AJ31: 0.087374 | AK31: 0.087374 | AL31: 0.087374 | AM31: 0.087374 | AN31: 0.087374 | AO31: 0.087374 | AP31: 0.087374 | AQ31: 0.087374 | AR31: 0.087374 | AS31: 0.087374 | AT31: 0.087374 | AU31: 0.087374 | AV31: 0.087374 | AW31: 0.087374 | AX31: 0.087374 | AY31: 0.087374 | AZ31: 0.087374 | BA31: 0.087374 | BB31: 0.087374 | BC31: 0.087374 | BD31: 0.087374 | BE31: 0.087374 | BF31: 0.087374 | BG31: 0.087374 | BH31: 0.087374 | BI31: 0.087374 | BJ31: 0.087374 | BK31: 0.087374 | BL31: 0.087374 | BM31: 0.087374
C32: ORG_DCOLL | D32: Recolección diferenciada de residuos orgánicos | E32: 0.040256742 | F32: 0.041913171 | G32: 0.04323439 | H32: 0.047073943 | I32: 0.04619 | J32: 0.0462 | K32: 0.04559 | L32: 0.06437 | M32: 0.067014 | N32: 0.06264 | O32: 0.063792 | P32: 0.064232 | Q32: 0.0670308 | R32: 0.070626 | S32: 0.070626 | T32: 0.070626 | U32: 0.070626 | V32: 0.070626 | W32: 0.070626 | X32: 0.070626 | Y32: 0.070626 | Z32: 0.070626 | AA32: 0.070626 | AB32: 0.070626 | AC32: 0.070626 | AD32: 0.070626 | AE32: 0.070626 | AF32: 0.070626 | AG32: 0.070626 | AH32: 0.070626 | AI32: 0.070626 | AJ32: 0.070626 | AK32: 0.070626 | AL32: 0.070626 | AM32: 0.070626 | AN32: 0.070626 | AO32: 0.070626 | AP32: 0.070626 | AQ32: 0.070626 | AR32: 0.070626 | AS32: 0.070626 | AT32: 0.070626 | AU32: 0.070626 | AV32: 0.070626 | AW32: 0.070626 | AX32: 0.070626 | AY32: 0.070626 | AZ32: 0.070626 | BA32: 0.070626 | BB32: 0.070626 | BC32: 0.070626 | BD32: 0.070626 | BE32: 0.070626 | BF32: 0.070626 | BG32: 0.070626 | BH32: 0.070626 | BI32: 0.070626 | BJ32: 0.070626 | BK32: 0.070626 | BL32: 0.070626 | BM32: 0.070626
C33: BLEND_NO_DCOLL | D33: Recolección no diferenciada de residuos mezclados | E33: 0.91221818 | F33: 0.90652727 | G33: 0.90083636 | H33: 0.89514545 | I33: 0.9 | J33: 0.89 | K33: 0.903 | L33: 0.843 | M33: 0.847 | N33: 0.856 | O33: 0.856 | P33: 0.85 | Q33: 0.834 | R33: 0.842 | S33: 0.84 | T33: 0.84 | U33: 0.84 | V33: 0.84 | W33: 0.84 | X33: 0.84 | Y33: 0.84 | Z33: 0.84 | AA33: 0.84 | AB33: 0.84 | AC33: 0.84 | AD33: 0.84 | AE33: 0.84 | AF33: 0.84 | AG33: 0.84 | AH33: 0.84 | AI33: 0.84 | AJ33: 0.84 | AK33: 0.84 | AL33: 0.84 | AM33: 0.84 | AN33: 0.84 | AO33: 0.84 | AP33: 0.84 | AQ33: 0.84 | AR33: 0.84 | AS33: 0.84 | AT33: 0.84 | AU33: 0.84 | AV33: 0.84 | AW33: 0.84 | AX33: 0.84 | AY33: 0.84 | AZ33: 0.84 | BA33: 0.84 | BB33: 0.84 | BC33: 0.84 | BD33: 0.84 | BE33: 0.84 | BF33: 0.84 | BG33: 0.84 | BH33: 0.84 | BI33: 0.84 | BJ33: 0.84 | BK33: 0.84 | BL33: 0.84 | BM33: 0.84
C34: BLEND_NO_COLL | D34: No recolección de residuos | E34: 0 | F34: 0 | G34: 0 | H34: 0 | I34: 0 | J34: 0 | K34: 0 | L34: 0 | M34: 0 | N34: 0 | O34: 0 | P34: 0 | Q34: 0 | R34: 0 | S34: 0 | T34: 0 | U34: 0 | V34: 0 | W34: 0 | X34: 0 | Y34: 0 | Z34: 0 | AA34: 0 | AB34: 0 | AC34: 0 | AD34: 0 | AE34: 0 | AF34: 0 | AG34: 0 | AH34: 0 | AI34: 0 | AJ34: 0 | AK34: 0 | AL34: 0 | AM34: 0 | AN34: 0 | AO34: 0 | AP34: 0 | AQ34: 0 | AR34: 0 | AS34: 0 | AT34: 0 | AU34: 0 | AV34: 0 | AW34: 0 | AX34: 0 | AY34: 0 | AZ34: 0 | BA34: 0 | BB34: 0 | BC34: 0 | BD34: 0 | BE34: 0 | BF34: 0 | BG34: 0 | BH34: 0 | BI34: 0 | BJ34: 0 | BK34: 0 | BL34: 0 | BM34: 0
E35: =SUM(E31:E34) -> 1 | F35: =SUM(F31:F34) -> 1 | G35: =SUM(G31:G34) -> 1 | H35: =SUM(H31:H34) -> 1 | I35: =SUM(I31:I34) -> 1 | J35: =SUM(J31:J34) -> 1 | K35: =SUM(K31:K34) -> 1 | L35: =SUM(L31:L34) -> 0.99686 | ... BM35: =SUM(BM31:BM34) -> 0.998
C36: Etapa 1: Separación en la fuente
C38: ORG_SS | D38: Separación de residuos orgánicos en la fuente | E38: =E32 -> 0.040256742 | F38: =F32 -> 0.041913171 | G38: =G32 -> 0.04323439 | H38: =H32 -> 0.047073943 | I38: =I32 -> 0.04619 | J38: =J32 -> 0.0462 | K38: =K32 -> 0.04559 | L38: =L32 -> 0.06437 | ... P38: =P32 -> 0.064232 | Q38: =Q31 -> 0.0989692 | R38: =R31 -> 0.087374 | S38: =S31 -> 0.087374 | T38: 0.087374 | U38: 0.087374 | V38: 0.087374 | W38: 0.087374 | X38: 0.087374 | Y38: 0.087374 | Z38: 0.087374 | AA38: 0.087374 | AB38: 0.087374 | AC38: 0.087374 | AD38: 0.087374 | AE38: 0.087374 | AF38: 0.087374 | AG38: 0.087374 | AH38: 0.087374 | AI38: 0.087374 | AJ38: 0.087374 | AK38: 0.087374 | AL38: 0.087374 | AM38: 0.087374 | AN38: 0.087374 | AO38: 0.087374 | AP38: 0.087374 | AQ38: 0.087374 | AR38: 0.087374 | AS38: 0.087374 | AT38: 0.087374 | AU38: 0.087374 | AV38: 0.087374 | AW38: 0.087374 | AX38: 0.087374 | AY38: 0.087374 | AZ38: 0.087374 | BA38: 0.087374 | BB38: 0.087374 | BC38: 0.087374 | BD38: 0.087374 | BE38: 0.087374 | BF38: 0.087374 | BG38: 0.087374 | BH38: 0.087374 | BI38: 0.087374 | BJ38: 0.087374 | BK38: 0.087374 | BL38: 0.087374 | BM38: 0.087374
C39: INORG_SS | D39: Separación de residuos inorgánicos en la fuente | E39: =E31 -> 0.047525076 | F39: =F31 -> 0.051559556 | G39: =G31 -> 0.055929246 | H39: =H31 -> 0.057780602 | I39: =I31 -> 0.05381 | J39: =J31 -> 0.0638 | K39: =K31 -> 0.05141 | L39: =L31 -> 0.08949 | ... P39: =P31 -> 0.083768 | Q39: =Q32 -> 0.0670308 | R39: =R32 -> 0.070626 | S39: =S32 -> 0.070626 | T39: 0.070626 | U39: 0.070626 | V39: 0.070626 | W39: 0.070626 | X39: 0.070626 | Y39: 0.070626 | Z39: 0.070626 | AA39: 0.070626 | AB39: 0.070626 | AC39: 0.070626 | AD39: 0.070626 | AE39: 0.070626 | AF39: 0.070626 | AG39: 0.070626 | AH39: 0.070626 | AI39: 0.070626 | AJ39: 0.070626 | AK39: 0.070626 | AL39: 0.070626 | AM39: 0.070626 | AN39: 0.070626 | AO39: 0.070626 | AP39: 0.070626 | AQ39: 0.070626 | AR39: 0.070626 | AS39: 0.070626 | AT39: 0.070626 | AU39: 0.070626 | AV39: 0.070626 | AW39: 0.070626 | AX39: 0.070626 | AY39: 0.070626 | AZ39: 0.070626 | BA39: 0.070626 | BB39: 0.070626 | BC39: 0.070626 | BD39: 0.070626 | BE39: 0.070626 | BF39: 0.070626 | BG39: 0.070626 | BH39: 0.070626 | BI39: 0.070626 | BJ39: 0.070626 | BK39: 0.070626 | BL39: 0.070626 | BM39: 0.070626
C40: NO_SS | D40: No separación de residuos en la fuente | E40: =E33 -> 0.91221818 | F40: =F33 -> 0.90652727 | G40: =G33 -> 0.90083636 | H40: =H33 -> 0.89514545 | I40: =I33 -> 0.9 | J40: =J33 -> 0.89 | K40: =K33 -> 0.903 | L40: =L33 -> 0.843 | ... S40: =S33 -> 0.84 | T40: 0.84 | U40: 0.84 | V40: 0.84 | W40: 0.84 | X40: 0.84 | Y40: 0.84 | Z40: 0.84 | AA40: 0.84 | AB40: 0.84 | AC40: 0.84 | AD40: 0.84 | AE40: 0.84 | AF40: 0.84 | AG40: 0.84 | AH40: 0.84 | AI40: 0.84 | AJ40: 0.84 | AK40: 0.84 | AL40: 0.84 | AM40: 0.84 | AN40: 0.84 | AO40: 0.84 | AP40: 0.84 | AQ40: 0.84 | AR40: 0.84 | AS40: 0.84 | AT40: 0.84 | AU40: 0.84 | AV40: 0.84 | AW40: 0.84 | AX40: 0.84 | AY40: 0.84 | AZ40: 0.84 | BA40: 0.84 | BB40: 0.84 | BC40: 0.84 | BD40: 0.84 | BE40: 0.84 | BF40: 0.84 | BG40: 0.84 | BH40: 0.84 | BI40: 0.84 | BJ40: 0.84 | BK40: 0.84 | BL40: 0.84 | BM40: 0.84
E41: =SUM(E38:E40) -> 1 | F41: =SUM(F38:F40) -> 1 | G41: =SUM(G38:G40) -> 1 | H41: =SUM(H38:H40) -> 1 | I41: =SUM(I38:I40) -> 1 | J41: =SUM(J38:J40) -> 1 | K41: =SUM(K38:K40) -> 1 | L41: =SUM(L38:L40) -> 0.99686 | ... BM41: =SUM(BM38:BM40) -> 0.998
D43: Inorgánicos u otros sin emisiones
D44: Compostaje | E44: 0.0055 | F44: 0.0064 | G44: 0.0073 | H44: 0.0222 | I44: 0.0372 | J44: 0.0322 | K44: 0.0272 | L44: 0.0305 | M44: 0.0338 | N44: 0.0353 | O44: 0.0368 | P44: 0.0385 | Q44: 0.0337 | R44: 0.0356 | S44: 0.0376 | T44: 0.0396 | U44: 0.0417 | V44: 0.0437 | W44: 0.0459 | X44: 0.048 | Y44: 0.0502 | Z44: 0.0512 | AA44: 0.0521 | AB44: 0.0531 | AC44: 0.0541 | AD44: 0.0551
D45: Sitios gestionados | E45: 1.2472 | F45: 1.354 | G45: 1.4482 | H45: 1.5746 | I45: 1.7108 | J45: 1.9967 | K45: 2.218 | L45: 2.3477 | M45: 2.4618 | N45: 2.4778 | O45: 2.4921 | P45: 2.6399 | Q45: 2.7492 | R45: 2.9082 | S45: 3.0701 | T45: 3.2348 | U45: 3.4022 | V45: 3.5721 | W45: 3.7446 | X45: 3.9197 | Y45: 4.097 | Z45: 4.177 | AA45: 4.2571 | AB45: 4.3372 | AC45: 4.4173 | AD45: 4.4973
D46: Sitios no gestionados | E46: 1.1267 | F46: 1.1059 | G46: 1.0876 | H46: 1.3072 | I46: 1.5439 | J46: 1.0758 | K46: 0.7133 | L46: 0.5753 | M46: 0.4538 | N46: 0.4447 | O46: 0.4366 | P46: 0.3745 | Q46: 0.3847 | R46: 0.4069 | S46: 0.4296 | T46: 0.4526 | U46: 0.476 | V46: 0.4998 | W46: 0.5239 | X46: 0.5484 | Y46: 0.5733 | Z46: 0.5844 | AA46: 0.5957 | AB46: 0.6069 | AC46: 0.6181 | AD46: 0.6293
D47: Incineranción contralada | E47: 0.0091 | F47: 0.0097 | G47: 0.0104 | H47: 0.0108 | I47: 0.0113 | J47: 0.0112 | K47: 0.0112 | L47: 0.0114 | M47: 0.0116 | N47: 0.0151 | O47: 0.0193 | P47: 0.0091 | Q47: 0.0137 | R47: 0.014492478 | S47: 0.015299452 | T47: 0.016119906 | U47: 0.016954093 | V47: 0.017800997 | W47: 0.018660617 | X47: 0.019532953 | Y47: 0.020416479 | Z47: 0.020815261 | AA47: 0.021214552 | AB47: 0.021613589 | AC47: 0.022012625 | AD47: 0.022411408 | AE47: 0.022411408 | AF47: 0.022411408 | AG47: 0.022411408 | AH47: 0.022411408 | AI47: 0.022411408 | AJ47: 0.022411408 | AK47: 0.022411408 | AL47: 0.022411408 | AM47: 0.022411408 | AN47: 0.022411408 | AO47: 0.022411408 | AP47: 0.022411408 | AQ47: 0.022411408 | AR47: 0.022411408 | AS47: 0.022411408 | AT47: 0.022411408 | AU47: 0.022411408 | AV47: 0.022411408 | AW47: 0.022411408 | AX47: 0.022411408 | AY47: 0.022411408 | AZ47: 0.022411408 | BA47: 0.022411408 | BB47: 0.022411408 | BC47: 0.022411408 | BD47: 0.022411408 | BE47: 0.022411408 | BF47: 0.022411408 | BG47: 0.022411408 | BH47: 0.022411408 | BI47: 0.022411408 | BJ47: 0.022411408 | BK47: 0.022411408 | BL47: 0.022411408 | BM47: 0.022411408
D49: Residuos sólidos (Mt)
...

Sheet ParticipacionTechsSolidosTN (
D1: Ecuador | E1: 2010 | F1: 2011 | G1: 2012 | H1: 2013 | I1: 2014 | J1: 2015 | K1: 2016 | L1: 2017 | M1: 2018 | N1: 2019 | O1: 2020 | P1: 2021 | Q1: 2022 | R1: 2023 | S1: 2024 | T1: 2025 | U1: 2026 | V1: 2027 | W1: 2028 | X1: 2029 | Y1: 2030 | Z1: 2031 | AA1: 2032 | AB1: 2033 | AC1: 2034 | AD1: 2035
D4: Residuos sólidos (PORCENTAJES)
C6: Códificación OSeMOSYS | D6: Tendencial Nacional
C8: Etapa 4: Disposición final
C9: INORG_RCY_OS | D9: Reciclaje de residuos inorgánicos separados en sitio de disposición final | E9: =E19-E15 -> 0.0084026138 | F9: =F19-F15 -> 0.0083393746 | G9: =G19-G15 -> 0.0082482141 | H9: =H19-H15 -> 0.0084640956 | I9: =I19-I15 -> 0.0086310534 | J9: =J19-J15 -> 0.0085256798 | K9: =K19-K15 -> 0.0084252217 | L9: =L19-L15 -> 0.0083788193 | ... AD9: =AD19-AD15 -> 0.008111047
C10: AD | D10: Digestión Anaerobica | E10: 0 | F10: 0 | G10: 0 | H10: 0 | I10: 0 | J10: 0 | K10: 0 | L10: 0 | M10: 0 | N10: 0 | O10: 0 | P10: 0 | Q10: 0 | R10: 0 | S10: 0 | T10: 0 | U10: 0 | V10: 0 | W10: 0 | X10: 0 | Y10: 0 | Z10: 0 | AA10: 0 | AB10: 0 | AC10: 0 | AD10: 0
C11: COMPOST | D11: Compostaje | E11: 0.016331389 | F11: 0.018335775 | G11: 0.020436365 | H11: 0.0236 | I11: 0.0236 | J11: 0.0236 | K11: 0.0236 | L11: 0.0236 | M11: 0.0236 | N11: 0.0236 | O11: 0.0236 | P11: 0.0236 | Q11: 0.035046692 | R11: 0.035175404 | S11: 0.035175404 | T11: 0.035175404 | U11: 0.035175404 | V11: 0.035175404 | W11: 0.035175404 | X11: 0.035175404 | Y11: 0.035175404 | Z11: 0.035175404 | AA11: 0.035175404 | AB11: 0.035175404 | AC11: 0.035175404 | AD11: 0.035175404
C12: LANDFILL | D12: Relleno sanitario | E12: 0.33186663 | F12: 0.33972032 | G12: 0.34750426 | H12: 0.35486065 | I12: 0.3681148 | J12: 0.40640579 | K12: 0.41951566 | L12: 0.44091141 | M12: 0.43362624 | N12: 0.46549632 | O12: 0.48722158 | P12: 0.49783433 | Q12: 0.52010075 | R12: 0.5288252 | S12: 0.5288252 | T12: 0.5288252 | U12: 0.5288252 | V12: 0.5288252 | W12: 0.5288252 | X12: 0.5288252 | Y12: 0.5288252 | Z12: 0.5288252 | AA12: 0.5288252 | AB12: 0.5288252 | AC12: 0.5288252 | AD12: 0.5288252
C13: NO_CONTR_OD | D13: Botadero a cielo abierto | E13: 0.64116198 | F13: 0.63130391 | G13: 0.62141938 | H13: 0.61089935 | I13: 0.5976452 | J13: 0.55935421 | K13: 0.54624434 | L13: 0.52484859 | M13: 0.53213376 | N13: 0.50026368 | O13: 0.47853842 | P13: 0.46792567 | Q13: 0.43421255 | R13: 0.4253594 | S13: 0.4253594 | T13: 0.4253594 | U13: 0.4253594 | V13: 0.4253594 | W13: 0.4253594 | X13: 0.4253594 | Y13: 0.4253594 | Z13: 0.4253594 | AA13: 0.4253594 | AB13: 0.4253594 | AC13: 0.4253594 | AD13: 0.4253594
C14: COPROC | D14: Coprocesamiento | E14: 0 | F14: 0 | G14: 0 | H14: 0 | I14: 0 | J14: 0 | K14: 0 | L14: 0 | M14: 0 | N14: 0 | O14: 0 | P14: 0 | Q14: 0 | R14: 0 | S14: 0 | T14: 0 | U14: 0 | V14: 0 | W14: 0 | X14: 0 | Y14: 0 | Z14: 0 | AA14: 0 | AB14: 0 | AC14: 0 | AD14: 0
C15: INCIN | D15: Incineranción contralada | E15: =E42/E77 -> 0.0022373862 | F15: =F42/F77 -> 0.0023006254 | G15: =G42/G77 -> 0.0023917859 | H15: =H42/H77 -> 0.0021759044 | I15: =I42/I77 -> 0.0020089466 | J15: =J42/J77 -> 0.0021143202 | K15: =K42/K77 -> 0.0022147783 | L15: =L42/L77 -> 0.0022611807 | ... AD15: =AD42/AD77 -> 0.002528953
C16: OPEN_BURN | D16: Quema a cielo abierto | E16: 0 | F16: 0 | G16: 0 | H16: 0 | I16: 0 | J16: 0 | K16: 0 | L16: 0 | M16: 0 | N16: 0 | O16: 0 | P16: 0 | Q16: 0 | R16: 0 | S16: 0 | T16: 0 | U16: 0 | V16: 0 | W16: 0 | X16: 0 | Y16: 0 | Z16: 0 | AA16: 0 | AB16: 0 | AC16: 0 | AD16: 0
C17: SIT_CLAN | D17: Disposición en sitios clandestinos | E17: 0 | F17: 0 | G17: 0 | H17: 0 | I17: 0 | J17: 0 | K17: 0 | L17: 0 | M17: 0 | N17: 0 | O17: 0 | P17: 0 | Q17: 0 | R17: 0 | S17: 0 | T17: 0 | U17: 0 | V17: 0 | W17: 0 | X17: 0 | Y17: 0 | Z17: 0 | AA17: 0 | AB17: 0 | AC17: 0 | AD17: 0
E18: =SUM(E9:E17) -> 1 | F18: =SUM(F9:F17) -> 1 | G18: =SUM(G9:G17) -> 1 | H18: =SUM(H9:H17) -> 1 | I18: =SUM(I9:I17) -> 1 | J18: =SUM(J9:J17) -> 1 | K18: =SUM(K9:K17) -> 1 | L18: =SUM(L9:L17) -> 1 | ... AD18: =SUM(AD9:AD17) -> 1
D19: Reciclaje de residuos inorgánicos separados en sitio de disposición final | E19: 0.01064 | F19: 0.01064 | G19: 0.01064 | H19: 0.01064 | I19: 0.01064 | J19: 0.01064 | K19: 0.01064 | L19: 0.01064 | M19: 0.01064 | N19: 0.01064 | O19: 0.01064 | P19: 0.01064 | Q19: 0.01064 | R19: 0.01064 | S19: 0.01064 | T19: 0.01064 | U19: 0.01064 | V19: 0.01064 | W19: 0.01064 | X19: 0.01064 | Y19: 0.01064 | Z19: 0.01064 | AA19: 0.01064 | AB19: 0.01064 | AC19: 0.01064 | AD19: 0.01064
C21: Etapa 3: Separación en el sitio de disposición final
C22: OSS_INORG | D22: Separación de residuos inorgánicos en sitio de disposición final | E22: =E9 -> 0.0084026138 | F22: =F9 -> 0.0083393746 | G22: =G9 -> 0.0082482141 | H22: =H9 -> 0.0084640956 | I22: =I9 -> 0.0086310534 | J22: =J9 -> 0.0085256798 | K22: =K9 -> 0.0084252217 | L22: =L9 -> 0.0083788193 | ... AD22: =AD9 -> 0.008111047
C23: OSS_ORG | D23: Separación de residuos orgánicos en sitio de disposición final | E23: =E11 -> 0.016331389 | F23: =F11 -> 0.018335775 | G23: =G11 -> 0.020436365 | H23: =H11 -> 0.0236 | I23: =I11 -> 0.0236 | J23: =J11 -> 0.0236 | K23: =K11 -> 0.0236 | L23: =L11 -> 0.0236 | ... AD23: =AD11 -> 0.035175404
C24: NO_OSS_BLEND | D24: No separación de residuos mezclados en sitio de disposición final | E24: =1-E23-E22 -> 0.975266 | F24: =1-F23-F22 -> 0.97332485 | G24: =1-G23-G22 -> 0.97131542 | H24: =1-H23-H22 -> 0.9679359 | I24: =1-I23-I22 -> 0.96776895 | J24: =1-J23-J22 -> 0.96787432 | K24: =1-K23-K22 -> 0.96797478 | L24: =1-L23-L22 -> 0.96802118 | ... AD24: =1-AD23-AD22 -> 0.95671355
C25: NO_OSS_NO_COLL | D25: No separación de residuos mezclados no recolectados | E25: 0 | F25: 0 | G25: 0 | H25: 0 | I25: 0 | J25: 0 | K25: 0 | L25: 0 | M25: 0 | N25: 0 | O25: 0 | P25: 0 | Q25: 0 | R25: 0 | S25: 0 | T25: 0 | U25: 0 | V25: 0 | W25: 0 | X25: 0 | Y25: 0 | Z25: 0 | AA25: 0 | AB25: 0 | AC25: 0 | AD25: 0
E26: =E22+E23+E24 -> 1 | F26: =F22+F23+F24 -> 1 | G26: =G22+G23+G24 -> 1 | H26: =H22+H23+H24 -> 1 | I26: =I22+I23+I24 -> 1 | J26: =J22+J23+J24 -> 1 | K26: =K22+K23+K24 -> 1 | L26: =L22+L23+L24 -> 1 | ... AD26: =AD22+AD23+AD24 -> 1
C27: Etapa 2: Recolección
C28: INORG_DCOLL | D28: Recolección diferenciada de residuos inorgánicos | E28: =E22 -> 0.0084026138 | F28: =F22 -> 0.0083393746 | G28: =G22 -> 0.0082482141 | H28: =H22 -> 0.0084640956 | I28: =I22 -> 0.0086310534 | J28: =J22 -> 0.0085256798 | K28: =K22 -> 0.0084252217 | L28: =L22 -> 0.0083788193 | ... AD28: =AD22 -> 0.008111047
C29: ORG_DCOLL | D29: Recolección diferenciada de residuos orgánicos | E29: =E23 -> 0.016331389 | F29: =F23 -> 0.018335775 | G29: =G23 -> 0.020436365 | H29: =H23 -> 0.0236 | I29: =I23 -> 0.0236 | J29: =J23 -> 0.0236 | K29: =K23 -> 0.0236 | L29: =L23 -> 0.0236 | ... AD29: =AD23 -> 0.035175404
C30: BLEND_NO_DCOLL | D30: Recolección no diferenciada de residuos mezclados | E30: =1-E29-E28 -> 0.975266 | F30: =1-F29-F28 -> 0.97332485 | G30: =1-G29-G28 -> 0.97131542 | H30: =1-H29-H28 -> 0.9679359 | I30: =1-I29-I28 -> 0.96776895 | J30: =1-J29-J28 -> 0.96787432 | K30: =1-K29-K28 -> 0.96797478 | L30: =1-L29-L28 -> 0.96802118 | ... AD30: =1-AD29-AD28 -> 0.95671355
C31: BLEND_NO_COLL | D31: No recolección de residuos | E31: 0 | F31: 0 | G31: 0 | H31: 0 | I31: 0 | J31: 0 | K31: 0 | L31: 0 | M31: 0 | N31: 0 | O31: 0 | P31: 0 | Q31: 0 | R31: 0 | S31: 0 | T31: 0 | U31: 0 | V31: 0 | W31: 0 | X31: 0 | Y31: 0 | Z31: 0 | AA31: 0 | AB31: 0 | AC31: 0 | AD31: 0
E32: =SUM(E28:E31) -> 1 | F32: =SUM(F28:F31) -> 1 | G32: =SUM(G28:G31) -> 1 | H32: =SUM(H28:H31) -> 1 | I32: =SUM(I28:I31) -> 1 | J32: =SUM(J28:J31) -> 1 | K32: =SUM(K28:K31) -> 1 | L32: =SUM(L28:L31) -> 1 | ... AD32: =SUM(AD28:AD31) -> 1
C33: Etapa 1: Separación en la fuente
C35: ORG_SS | D35: Separación de residuos orgánicos en la fuente | E35: =E29 -> 0.016331389 | F35: =F29 -> 0.018335775 | G35: =G29 -> 0.020436365 | H35: =H29 -> 0.0236 | I35: =I29 -> 0.0236 | J35: =J29 -> 0.0236 | K35: =K29 -> 0.0236 | L35: =L29 -> 0.0236 | ... AD35: =AD29 -> 0.035175404
C36: INORG_SS | D36: Separación de residuos inorgánicos en la fuente | E36: =E28 -> 0.0084026138 | F36: =F28 -> 0.0083393746 | G36: =G28 -> 0.0082482141 | H36: =H28 -> 0.0084640956 | I36: =I28 -> 0.0086310534 | J36: =J28 -> 0.0085256798 | K36: =K28 -> 0.0084252217 | L36: =L28 -> 0.0083788193 | ... AD36: =AD28 -> 0.008111047
C37: NO_SS | D37: No separación de residuos en la fuente | E37: =E30 -> 0.975266 | F37: =F30 -> 0.97332485 | G37: =G30 -> 0.97131542 | H37: =H30 -> 0.9679359 | I37: =I30 -> 0.96776895 | J37: =J30 -> 0.96787432 | K37: =K30 -> 0.96797478 | L37: =L30 -> 0.96802118 | ... AD37: =AD30 -> 0.95671355
E38: =SUM(E35:E37) -> 1 | F38: =SUM(F35:F37) -> 1 | G38: =SUM(G35:G37) -> 1 | H38: =SUM(H35:H37) -> 1 | I38: =SUM(I35:I37) -> 1 | J38: =SUM(J35:J37) -> 1 | K38: =SUM(K35:K37) -> 1 | L38: =SUM(L35:L37) -> 1 | ... AD38: =SUM(AD35:AD37) -> 1
D42: Incineranción contralada | E42: 0.0091 | F42: 0.0097 | G42: 0.0104 | H42: 0.0108 | I42: 0.0113 | J42: 0.0112 | K42: 0.0112 | L42: 0.0114 | M42: 0.0116 | N42: 0.0151 | O42: 0.0193 | P42: 0.0091 | Q42: 0.0137 | R42: 0.014492478 | S42: 0.015299452 | T42: 0.016119906 | U42: 0.016954093 | V42: 0.017800997 | W42: 0.018660617 | X42: 0.019532953 | Y42: 0.020416479 | Z42: 0.020815261 | AA42: 0.021214552 | AB42: 0.021613589 | AC42: 0.022012625 | AD42: 0.022411408
D44: Residuos sólidos (Mt)
C46: Códificación OSeMOSYS | D46: Tendencial Nacional
C48: Etapa 4: Disposición final
C49: INORG_RCY_OS | D49: Reciclaje de residuos inorgánicos separados en sitio de disposición final | E49: =E9*E77 -> 0.034175496 | F49: =F9*F77 -> 0.035160845 | G49: =G9*G77 -> 0.035865011 | H49: =H9*H77 -> 0.042011143 | I49: =I9*I77 -> 0.048548281 | J49: =J9*J77 -> 0.045162325 | K49: =K9*K77 -> 0.042605837 | L49: =L9*L77 -> 0.042242772 | ... AD49: =AD9*AD77 -> 0.07187954
C50: AD | D50: Digestión Anaerobica | E50: =E10*E77 -> 0 | F50: =F10*F77 -> 0 | G50: =G10*G77 -> 0 | H50: =H10*H77 -> 0 | I50: =I10*I77 -> 0 | J50: =J10*J77 -> 0 | K50: =K10*K77 -> 0 | L50: =L10*L77 -> 0 | ... AD50: =AD10*AD77 -> 0
C51: COMPOST | D51: Compostaje | E51: =E11*E77 -> 0.066423773 | F51: =F11*F77 -> 0.077308115 | G51: =G11*G77 -> 0.088861717 | H51: =H11*H77 -> 0.1171375 | I51: =I11*I77 -> 0.13274619 | J51: =J11*J77 -> 0.12501418 | K51: =K11*K77 -> 0.11934377 | L51: =L11*L77 -> 0.11898209 | ... AD51: =AD11*AD77 -> 0.31172201
C52: LANDFILL | D52: Relleno sanitario | E52: =E12*E77 -> 1.3497832 | F52: =F12*F77 -> 1.432344 | G52: =G12*G77 -> 1.5110233 | H52: =H12*H77 -> 1.7613343 | I52: =I12*I77 -> 2.0705863 | J52: =J12*J77 -> 2.1528172 | K52: =K12*K77 -> 2.1214653 | L52: =L12*L77 -> 2.2229051 | ... AD52: =AD12*AD77 -> 4.6864125
...

Sheet ParticipacionTechsSolidosPA
D1: Ecuador | E1: 2010 | F1: 2011 | G1: 2012 | H1: 2013 | I1: 2014 | J1: 2015 | K1: 2016 | L1: 2017 | M1: 2018 | N1: 2019 | O1: 2020 | P1: 2021 | Q1: 2022 | R1: 2023 | S1: 2024 | T1: 2025 | U1: 2026 | V1: 2027 | W1: 2028 | X1: 2029 | Y1: 2030 | Z1: 2031 | AA1: 2032 | AB1: 2033 | AC1: 2034 | AD1: 2035
D4: Residuos sólidos (PORCENTAJES)
C6: Códificación OSeMOSYS | D6: Plan de acción
C8: Etapa 4: Disposición final
C9: INORG_RCY_OS | D9: Reciclaje de residuos inorgánicos separados en sitio de disposición final | E9: 0.0084026138 | F9: 0.0083393746 | G9: 0.0082482141 | H9: 0.0084640956 | I9: 0.0086310534 | J9: 0.0085256798 | K9: 0.0084252217 | L9: 0.0083788193 | M9: 0.0083320206 | N9: 0.0076419641 | O9: 0.0070018194 | P9: 0.0088393707 | Q9: 0.0081496508 | R9: 0.0081653933 | S9: 0.008111047 | T9: 0.008111047 | U9: 0.008111047 | V9: 0.008111047 | W9: 0.008111047 | X9: 0.008111047 | Y9: 0.008111047 | Z9: 0.008111047 | AA9: 0.008111047 | AB9: 0.008111047 | AC9: 0.008111047 | AD9: 0.008111047
C10: AD | D10: Digestión Anaerobica | E10: 0 | F10: 0 | G10: 0 | H10: 0 | I10: 0 | J10: 0 | K10: 0 | L10: 0 | M10: 0 | N10: 0 | O10: 0 | P10: 0 | Q10: 0 | R10: 0 | S10: 0 | T10: 0 | U10: 0 | V10: 0 | W10: 0 | X10: 0 | Y10: 0 | Z10: 0 | AA10: 0 | AB10: 0 | AC10: 0 | AD10: 0
C11: COMPOST | D11: Compostaje | E11: 0.0163 | F11: 0.018357763 | G11: 0.020445242 | H11: 0.023632517 | I11: 0.023574172 | J11: 0.02361625 | K11: 0.023591528 | L11: 0.023603618 | M11: 0.023597294 | N11: 0.023607195 | O11: 0.023601267 | P11: 0.023605999 | Q11: 0.035046899 | R11: 0.035174592 | S11: 0.035175298 | T11: 0.035173593 | U11: 0.036800573 | V11: 0.038247872 | W11: 0.03961832 | X11: 0.040880015 | Y11: 0.04197381 | Z11: 0.043151742 | AA11: 0.044272479 | AB11: 0.045340699 | AC11: 0.046358757 | AD11: 0.047318576
C12: LANDFILL | D12: Relleno sanitario | E12: 0.33187087 | F12: 0.33971006 | G12: 0.34749785 | H12: 0.35485413 | I12: 0.36811751 | J12: 0.40640176 | K12: 0.41952313 | L12: 0.4409106 | M12: 0.43362082 | N12: 0.46548911 | O12: 0.48721411 | P12: 0.49782481 | Q12: 0.52010133 | R12: 0.52883332 | S12: 0.5288182 | T12: 0.50453205 | U12: 0.48799289 | V12: 0.49061879 | W12: 0.4930386 | X12: 0.5108242 | Y12: 0.51327406 | Z12: 0.51309814 | AA12: 0.51302428 | AB12: 0.51301267 | AC12: 0.51305696 | AD12: 0.51316528
C13: NO_CONTR_OD | D13: Botadero a cielo abierto | E13: 0.64118913 | F13: 0.63129218 | G13: 0.62141691 | H13: 0.61087335 | I13: 0.59766832 | J13: 0.55934199 | K13: 0.54624534 | L13: 0.52484578 | M13: 0.53214188 | N13: 0.50026369 | O13: 0.47854462 | P13: 0.46792919 | Q13: 0.43421177 | R13: 0.42535209 | S13: 0.4253665 | T13: 0.44965436 | U13: 0.46456653 | V13: 0.46049334 | W13: 0.45670308 | X13: 0.43765578 | Y13: 0.43411213 | Z13: 0.43311012 | AA13: 0.43206324 | AB13: 0.43100663 | AC13: 0.42994428 | AD13: 0.42887615
C14: COPROC | D14: Coprocesamiento | E14: 0 | F14: 0 | G14: 0 | H14: 0 | I14: 0 | J14: 0 | K14: 0 | L14: 0 | M14: 0 | N14: 0 | O14: 0 | P14: 0 | Q14: 0 | R14: 0 | S14: 0 | T14: 0 | U14: 0 | V14: 0 | W14: 0 | X14: 0 | Y14: 0 | Z14: 0 | AA14: 0 | AB14: 0 | AC14: 0 | AD14: 0
C15: INCIN | D15: Incineranción contralada | E15: 0.0022373862 | F15: 0.0023006254 | G15: 0.0023917859 | H15: 0.0021759044 | I15: 0.0020089466 | J15: 0.0021143202 | K15: 0.0022147783 | L15: 0.0022611807 | M15: 0.0023079794 | N15: 0.0029980359 | O15: 0.0036381806 | P15: 0.0018006293 | Q15: 0.0024903492 | R15: 0.0024746067 | S15: 0.002528953 | T15: 0.002528953 | U15: 0.002528953 | V15: 0.002528953 | W15: 0.002528953 | X15: 0.002528953 | Y15: 0.002528953 | Z15: 0.002528953 | AA15: 0.002528953 | AB15: 0.002528953 | AC15: 0.002528953 | AD15: 0.002528953
C16: OPEN_BURN | D16: Quema a cielo abierto | E16: 0 | F16: 0 | G16: 0 | H16: 0 | I16: 0 | J16: 0 | K16: 0 | L16: 0 | M16: 0 | N16: 0 | O16: 0 | P16: 0 | Q16: 0 | R16: 0 | S16: 0 | T16: 0 | U16: 0 | V16: 0 | W16: 0 | X16: 0 | Y16: 0 | Z16: 0 | AA16: 0 | AB16: 0 | AC16: 0 | AD16: 0
C17: SIT_CLAN | D17: Disposición en sitios clandestinos | E17: 0 | F17: 0 | G17: 0 | H17: 0 | I17: 0 | J17: 0 | K17: 0 | L17: 0 | M17: 0 | N17: 0 | O17: 0 | P17: 0 | Q17: 0 | R17: 0 | S17: 0 | T17: 0 | U17: 0 | V17: 0 | W17: 0 | X17: 0 | Y17: 0 | Z17: 0 | AA17: 0 | AB17: 0 | AC17: 0 | AD17: 0
E18: 1 | F18: 1 | G18: 1 | H18: 1 | I18: 1 | J18: 1 | K18: 1 | L18: 1 | M18: 1 | N18: 1 | O18: 1 | P18: 1 | Q18: 1 | R18: 1 | S18: 1 | T18: 1 | U18: 1 | V18: 1 | W18: 1 | X18: 1 | Y18: 1 | Z18: 1 | AA18: 1 | AB18: 1 | AC18: 1 | AD18: 1
C22: Etapa 3: Separación en el sitio de disposición final
C23: OSS_INORG | D23: Separación de residuos inorgánicos en sitio de disposición final | E23: =E10-E16 -> 0 | F23: =F10-F16 -> 0 | G23: =G10-G16 -> 0 | H23: =H10-H16 -> 0 | I23: =I10-I16 -> 0 | J23: =J10-J16 -> 0 | K23: =K10-K16 -> 0 | L23: =L10-L16 -> 0 | ... AD23: =AD10-AD16 -> 0
C24: OSS_ORG | D24: Separación de residuos orgánicos en sitio de disposición final | E24: =E12 -> 0.33187087 | F24: =F12 -> 0.33971006 | G24: =G12 -> 0.34749785 | H24: =H12 -> 0.35485413 | I24: =I12 -> 0.36811751 | J24: =J12 -> 0.40640176 | K24: =K12 -> 0.41952313 | L24: =L12 -> 0.4409106 | ... AD24: =AD12 -> 0.51316528
C25: NO_OSS_BLEND | D25: No separación de residuos mezclados en sitio de disposición final | E25: =1-E24-E23 -> 0.66812913 | F25: =1-F24-F23 -> 0.66028994 | G25: =1-G24-G23 -> 0.65250215 | H25: =1-H24-H23 -> 0.64514587 | I25: =1-I24-I23 -> 0.63188249 | J25: =1-J24-J23 -> 0.59359824 | K25: =1-K24-K23 -> 0.58047687 | L25: =1-L24-L23 -> 0.5590894 | ... AD25: =1-AD24-AD23 -> 0.48683472
C26: NO_OSS_NO_COLL | D26: No separación de residuos mezclados no recolectados | E26: 0 | F26: 0 | G26: 0 | H26: 0 | I26: 0 | J26: 0 | K26: 0 | L26: 0 | M26: 0 | N26: 0 | O26: 0 | P26: 0 | Q26: 0 | R26: 0 | S26: 0 | T26: 0 | U26: 0 | V26: 0 | W26: 0 | X26: 0 | Y26: 0 | Z26: 0 | AA26: 0 | AB26: 0 | AC26: 0 | AD26: 0
E27: =E23+E24+E25 -> 1 | F27: =F23+F24+F25 -> 1 | G27: =G23+G24+G25 -> 1 | H27: =H23+H24+H25 -> 1 | I27: =I23+I24+I25 -> 1 | J27: =J23+J24+J25 -> 1 | K27: =K23+K24+K25 -> 1 | L27: =L23+L24+L25 -> 1 | ... AD27: =AD23+AD24+AD25 -> 1
C28: Etapa 2: Recolección
C29: INORG_DCOLL | D29: Recolección diferenciada de residuos inorgánicos | E29: =E23 -> 0 | F29: =F23 -> 0 | G29: =G23 -> 0 | H29: =H23 -> 0 | I29: =I23 -> 0 | J29: =J23 -> 0 | K29: =K23 -> 0 | L29: =L23 -> 0 | ... AD29: =AD23 -> 0
C30: ORG_DCOLL | D30: Recolección diferenciada de residuos orgánicos | E30: =E24 -> 0.33187087 | F30: =F24 -> 0.33971006 | G30: =G24 -> 0.34749785 | H30: =H24 -> 0.35485413 | I30: =I24 -> 0.36811751 | J30: =J24 -> 0.40640176 | K30: =K24 -> 0.41952313 | L30: =L24 -> 0.4409106 | ... AD30: =AD24 -> 0.51316528
C31: BLEND_NO_DCOLL | D31: Recolección no diferenciada de residuos mezclados | E31: =1-E30-E29 -> 0.66812913 | F31: =1-F30-F29 -> 0.66028994 | G31: =1-G30-G29 -> 0.65250215 | H31: =1-H30-H29 -> 0.64514587 | I31: =1-I30-I29 -> 0.63188249 | J31: =1-J30-J29 -> 0.59359824 | K31: =1-K30-K29 -> 0.58047687 | L31: =1-L30-L29 -> 0.5590894 | ... AD31: =1-AD30-AD29 -> 0.48683472
C32: BLEND_NO_COLL | D32: No recolección de residuos | E32: 0 | F32: 0 | G32: 0 | H32: 0 | I32: 0 | J32: 0 | K32: 0 | L32: 0 | M32: 0 | N32: 0 | O32: 0 | P32: 0 | Q32: 0 | R32: 0 | S32: 0 | T32: 0 | U32: 0 | V32: 0 | W32: 0 | X32: 0 | Y32: 0 | Z32: 0 | AA32: 0 | AB32: 0 | AC32: 0 | AD32: 0
E33: =SUM(E29:E32) -> 1 | F33: =SUM(F29:F32) -> 1 | G33: =SUM(G29:G32) -> 1 | H33: =SUM(H29:H32) -> 1 | I33: =SUM(I29:I32) -> 1 | J33: =SUM(J29:J32) -> 1 | K33: =SUM(K29:K32) -> 1 | L33: =SUM(L29:L32) -> 1 | ... AD33: =SUM(AD29:AD32) -> 1
C34: Etapa 1: Separación en la fuente
C36: ORG_SS | D36: Separación de residuos orgánicos en la fuente | E36: =E30 -> 0.33187087 | F36: =F30 -> 0.33971006 | G36: =G30 -> 0.34749785 | H36: =H30 -> 0.35485413 | I36: =I30 -> 0.36811751 | J36: =J30 -> 0.40640176 | K36: =K30 -> 0.41952313 | L36: =L30 -> 0.4409106 | ... AD36: =AD30 -> 0.51316528
C37: INORG_SS | D37: Separación de residuos inorgánicos en la fuente | E37: =E29 -> 0 | F37: =F29 -> 0 | G37: =G29 -> 0 | H37: =H29 -> 0 | I37: =I29 -> 0 | J37: =J29 -> 0 | K37: =K29 -> 0 | L37: =L29 -> 0 | ... AD37: =AD29 -> 0
C38: NO_SS | D38: No separación de residuos en la fuente | E38: =E31 -> 0.66812913 | F38: =F31 -> 0.66028994 | G38: =G31 -> 0.65250215 | H38: =H31 -> 0.64514587 | I38: =I31 -> 0.63188249 | J38: =J31 -> 0.59359824 | K38: =K31 -> 0.58047687 | L38: =L31 -> 0.5590894 | ... AD38: =AD31 -> 0.48683472
E39: =SUM(E36:E38) -> 1 | F39: =SUM(F36:F38) -> 1 | G39: =SUM(G36:G38) -> 1 | H39: =SUM(H36:H38) -> 1 | I39: =SUM(I36:I38) -> 1 | J39: =SUM(J36:J38) -> 1 | K39: =SUM(K36:K38) -> 1 | L39: =SUM(L36:L38) -> 1 | ... AD39: =SUM(AD36:AD38) -> 1

Sheet ParticipacionTechsSolidosBAU
D1: Ecuador | E1: 2010 | F1: 2011 | G1: 2012 | H1: 2013 | I1: 2014 | J1: 2015 | K1: 2016 | L1: 2017 | M1: 2018 | N1: 2019 | O1: 2020 | P1: 2021 | Q1: 2022 | R1: 2023 | S1: 2024 | T1: 2025 | U1: 2026 | V1: 2027 | W1: 2028 | X1: 2029 | Y1: 2030 | Z1: 2031 | AA1: 2032 | AB1: 2033 | AC1: 2034 | AD1: 2035 | AE1: 2036 | AF1: 2037 | AG1: 2038 | AH1: 2039 | AI1: 2040 | AJ1: 2041 | AK1: 2042 | AL1: 2043 | AM1: 2044 | AN1: 2045 | AO1: 2046 | AP1: 2047 | AQ1: 2048 | AR1: 2049 | AS1: 2050 | AT1: 2051 | AU1: 2052 | AV1: 2053 | AW1: 2054 | AX1: 2055 | AY1: 2056 | AZ1: 2057 | BA1: 2058 | BB1: 2059 | BC1: 2060 | BD1: 2061 | BE1: 2062 | BF1: 2063 | BG1: 2064 | BH1: 2065 | BI1: 2066 | BJ1: 2067 | BK1: 2068 | BL1: 2069 | BM1: 2070
D4: Residuos sólidos (PORCENTAJES)
C6: Códificación OSeMOSYS | D6: BAU
C8: Etapa 4: Disposición final
C9: INORG_RCY_OS | D9: Reciclaje de residuos inorgánicos separados en sitio de disposición final | E9: =E22-E16 -> 0.021916659 | F9: =F22-F16 -> 0.022847277 | G9: =G22-G16 -> 0.023548848 | H9: =H22-H16 -> 0.026068461 | I9: =I22-I16 -> 0.025705053 | J9: =J22-J16 -> 0.02560568 | K9: =K22-K16 -> 0.025139222 | L9: =L22-L16 -> 0.036360819 | ... BM9: =BM22-BM16 -> 0.03263938
C10: AD | D10: Digestión Anaerobica | E10: 0 | F10: 0 | G10: 0 | H10: 0 | I10: 0 | J10: 0 | K10: 0 | L10: 0 | M10: 0 | N10: 0 | O10: 0 | P10: 0 | Q10: 0 | R10: 0 | S10: 0 | T10: 0 | U10: 0 | V10: 0 | W10: 0 | X10: 0 | Y10: 0 | Z10: 0 | AA10: 0 | AB10: 0 | AC10: 0 | AD10: 0 | AE10: 0 | AF10: 0 | AG10: 0 | AH10: 0 | AI10: 0 | AJ10: 0 | AK10: 0 | AL10: 0 | AM10: 0 | AN10: 0 | AO10: 0 | AP10: 0 | AQ10: 0 | AR10: 0 | AS10: 0 | AT10: 0 | AU10: 0 | AV10: 0 | AW10: 0 | AX10: 0 | AY10: 0 | AZ10: 0 | BA10: 0 | BB10: 0 | BC10: 0 | BD10: 0 | BE10: 0 | BF10: 0 | BG10: 0 | BH10: 0 | BI10: 0 | BJ10: 0 | BK10: 0 | BL10: 0 | BM10: 0
C11: COMPOST | D11: Compostaje | E11: 0.023762538 | F11: 0.025779778 | G11: 0.027964623 | H11: 0.028890301 | I11: 0.026905 | J11: 0.0319 | K11: 0.025705 | L11: 0.044745 | M11: 0.042993 | N11: 0.04068 | O11: 0.040104 | P11: 0.041884 | Q11: 0.0494846 | R11: 0.043687 | S11: 0.043687 | T11: =T26 -> 0.04238552 | U11: =U26 -> 0.041084041 | V11: =V26 -> 0.039782561 | W11: =W26 -> 0.038481082 | X11: =X26 -> 0.037179602 | Y11: =Y26 -> 0.035878123 | Z11: =Z26 -> 0.035924604 | AA11: =AA26 -> 0.035971086 | ... BM11: =BM26 -> 0.03666056
C12: LANDFILL_BG | D12: Relleno sanitario con quema biogas | E12: 0 | F12: 0 | G12: 0 | H12: 0 | I12: 0 | J12: 0 | K12: 0.00733391 | L12: 0.012651526 | M12: 0.012651526 | N12: 0.012651526 | O12: 0.012651526 | P12: 0.012651526 | Q12: 0.012651526 | R12: 0.012651526 | S12: 0.012651526 | T12: 0.012651526 | U12: 0.012651526 | V12: 0.012651526 | W12: 0.012651526 | X12: 0.012651526 | Y12: 0.012651526 | Z12: 0.012651526 | AA12: 0.012651526 | AB12: 0.012651526 | AC12: 0.012651526 | AD12: 0.012651526 | AE12: 0.012651526 | AF12: 0.012651526 | AG12: 0.012651526 | AH12: 0.012651526 | AI12: 0.012651526 | AJ12: 0.012651526 | AK12: 0.012651526 | AL12: 0.012651526 | AM12: 0.012651526 | AN12: 0.012651526 | AO12: 0.012651526 | AP12: 0.012651526 | AQ12: 0.012651526 | AR12: 0.012651526 | AS12: 0.012651526 | AT12: 0.012651526 | AU12: 0.012651526 | AV12: 0.012651526 | AW12: 0.012651526 | AX12: 0.012651526 | AY12: 0.012651526 | AZ12: 0.012651526 | BA12: 0.012651526 | BB12: 0.012651526 | BC12: 0.012651526 | BD12: 0.012651526 | BE12: 0.012651526 | BF12: 0.012651526 | BG12: 0.012651526 | BH12: 0.012651526 | BI12: 0.012651526 | BJ12: 0.012651526 | BK12: 0.012651526 | BL12: 0.012651526 | BM12: 0.012651526
C13: LANDFILL | D13: Relleno sanitario | E13: =E21-E12 -> 0.15345822 | F13: =F21-F12 -> 0.17844801 | G13: =G21-G12 -> 0.18257969 | H13: =H21-H12 -> 0.2533691 | I13: =I21-I12 -> 0.29152718 | J13: =J21-J12 -> 0.31758447 | K13: =K21-K12 -> 0.33372535 | L13: =L21-L12 -> 0.29154911 | ... R13: =R21-R12 -> 0.49881803 | S13: 1-% | T13: =1-T9-T11-T12-T14 -> 0.5121708 | U13: =1-U9-U11-U12-U14 -> 0.51499642 | V13: =1-V9-V11-V12-V14 -> 0.51781938 | W13: =1-W9-W11-W12-W14 -> 0.52063997 | X13: =1-X9-X11-X12-X14 -> 0.52345845 | Y13: =1-Y9-Y11-Y12-Y14 -> 0.52627475 | Z13: =1-Z9-Z11-Z12-Z14 -> 0.52560705 | AA13: =1-AA9-AA11-AA12-AA14 -> 0.5255169 | ... BM13: =1-BM9-BM11-BM12-BM14 -> 0.52322829
C14: NO_CONTR_OD | D14: Botadero a cielo abierto | E14: 0.7986252 | F14: 0.77062431 | G14: 0.76351506 | H14: 0.68949623 | I14: 0.65385382 | J14: 0.62279553 | K14: 0.60588174 | L14: 0.61243236 | M14: 0.61811308 | N14: 0.62144192 | O14: 0.58800241 | P14: 0.49931772 | Q14: 0.44896997 | R14: 0.40246785 | S14: 0.39482025 | T14: 0.39482025 | U14: 0.39482025 | V14: 0.39482025 | W14: 0.39482025 | X14: 0.39482025 | Y14: 0.39482025 | Z14: 0.39482025 | AA14: 0.39482025 | AB14: 0.39482025 | AC14: 0.39482025 | AD14: 0.39482025 | AE14: 0.39482025 | AF14: 0.39482025 | AG14: 0.39482025 | AH14: 0.39482025 | AI14: 0.39482025 | AJ14: 0.39482025 | AK14: 0.39482025 | AL14: 0.39482025 | AM14: 0.39482025 | AN14: 0.39482025 | AO14: 0.39482025 | AP14: 0.39482025 | AQ14: 0.39482025 | AR14: 0.39482025 | AS14: 0.39482025 | AT14: 0.39482025 | AU14: 0.39482025 | AV14: 0.39482025 | AW14: 0.39482025 | AX14: 0.39482025 | AY14: 0.39482025 | AZ14: 0.39482025 | BA14: 0.39482025 | BB14: 0.39482025 | BC14: 0.39482025 | BD14: 0.39482025 | BE14: 0.39482025 | BF14: 0.39482025 | BG14: 0.39482025 | BH14: 0.39482025 | BI14: 0.39482025 | BJ14: 0.39482025 | BK14: 0.39482025 | BL14: 0.39482025 | BM14: 0.39482025
C15: COPROC | D15: Coprocesamiento | E15: 0 | F15: 0 | G15: 0 | H15: 0 | I15: 0 | J15: 0 | K15: 0 | L15: 0 | M15: 0 | N15: 0 | O15: 0 | P15: 0 | Q15: 0 | R15: 0 | S15: 0 | T15: 0 | U15: 0 | V15: 0 | W15: 0 | X15: 0 | Y15: 0 | Z15: 0 | AA15: 0 | AB15: 0 | AC15: 0 | AD15: 0 | AE15: 0 | AF15: 0 | AG15: 0 | AH15: 0 | AI15: 0 | AJ15: 0 | AK15: 0 | AL15: 0 | AM15: 0 | AN15: 0 | AO15: 0 | AP15: 0 | AQ15: 0 | AR15: 0 | AS15: 0 | AT15: 0 | AU15: 0 | AV15: 0 | AW15: 0 | AX15: 0 | AY15: 0 | AZ15: 0 | BA15: 0 | BB15: 0 | BC15: 0 | BD15: 0 | BE15: 0 | BF15: 0 | BG15: 0 | BH15: 0 | BI15: 0 | BJ15: 0 | BK15: 0 | BL15: 0 | BM15: 0
C16: INCIN | D16: Incineranción contralada | E16: =E45/E81 -> 0.0022373862 | F16: =F45/F81 -> 0.0023006254 | G16: =G45/G81 -> 0.0023917859 | H16: =H45/H81 -> 0.0021759044 | I16: =I45/I81 -> 0.0020089466 | J16: =J45/J81 -> 0.0021143202 | K16: =K45/K81 -> 0.0022147783 | L16: =L45/L81 -> 0.0022611807 | ... BM16: =BM45/BM81 -> 0.001868321
C17: OPEN_BURN | D17: Quema a cielo abierto | E17: 0 | F17: 0 | G17: 0 | H17: 0 | I17: 0 | J17: 0 | K17: 0 | L17: 0 | M17: 0 | N17: 0 | O17: 0 | P17: 0 | Q17: 0 | R17: 0 | S17: 0 | T17: 0 | U17: 0 | V17: 0 | W17: 0 | X17: 0 | Y17: 0 | Z17: 0 | AA17: 0 | AB17: 0 | AC17: 0 | AD17: 0 | AE17: 0 | AF17: 0 | AG17: 0 | AH17: 0 | AI17: 0 | AJ17: 0 | AK17: 0 | AL17: 0 | AM17: 0 | AN17: 0 | AO17: 0 | AP17: 0 | AQ17: 0 | AR17: 0 | AS17: 0 | AT17: 0 | AU17: 0 | AV17: 0 | AW17: 0 | AX17: 0 | AY17: 0 | AZ17: 0 | BA17: 0 | BB17: 0 | BC17: 0 | BD17: 0 | BE17: 0 | BF17: 0 | BG17: 0 | BH17: 0 | BI17: 0 | BJ17: 0 | BK17: 0 | BL17: 0 | BM17: 0
C18: SIT_CLAN | D18: Disposición en sitios clandestinos | E18: 0 | F18: 0 | G18: 0 | H18: 0 | I18: 0 | J18: 0 | K18: 0 | L18: 0 | M18: 0 | N18: 0 | O18: 0 | P18: 0 | Q18: 0 | R18: 0 | S18: 0 | T18: 0 | U18: 0 | V18: 0 | W18: 0 | X18: 0 | Y18: 0 | Z18: 0 | AA18: 0 | AB18: 0 | AC18: 0 | AD18: 0 | AE18: 0 | AF18: 0 | AG18: 0 | AH18: 0 | AI18: 0 | AJ18: 0 | AK18: 0 | AL18: 0 | AM18: 0 | AN18: 0 | AO18: 0 | AP18: 0 | AQ18: 0 | AR18: 0 | AS18: 0 | AT18: 0 | AU18: 0 | AV18: 0 | AW18: 0 | AX18: 0 | AY18: 0 | AZ18: 0 | BA18: 0 | BB18: 0 | BC18: 0 | BD18: 0 | BE18: 0 | BF18: 0 | BG18: 0 | BH18: 0 | BI18: 0 | BJ18: 0 | BK18: 0 | BL18: 0 | BM18: 0
E19: =SUM(E9:E18) -> 1 | F19: =SUM(F9:F18) -> 1 | G19: =SUM(G9:G18) -> 1 | H19: =SUM(H9:H18) -> 1 | I19: =SUM(I9:I18) -> 1 | J19: =SUM(J9:J18) -> 1 | K19: =SUM(K9:K18) -> 1 | L19: =SUM(L9:L18) -> 1 | ... BM19: =SUM(BM9:BM18) -> 1.0018683
D21: Relleno sanitario | E21: 0.15345822 | F21: 0.17844801 | G21: 0.18257969 | H21: 0.2533691 | I21: 0.29152718 | J21: 0.31758447 | K21: 0.34105926 | L21: 0.30420064 | M21: 0.29868552 | N21: 0.30029408 | O21: 0.33361839 | P21: 0.42025908 | Q21: 0.46132695 | R21: 0.51146955 | S21: 0.52365633
D22: Reciclaje de residuos inorgánicos separados en sitio de disposición final | E22: 0.024154045 | F22: 0.025147903 | G22: 0.025940634 | H22: 0.028244366 | I22: 0.027714 | J22: 0.02772 | K22: 0.027354 | L22: 0.038622 | M22: 0.0402084 | N22: 0.037584 | O22: 0.0382752 | P22: 0.0385392 | Q22: 0.04021848 | R22: 0.0423756 | S22: 0.0423756 | T22: 0.04091826 | U22: 0.039460921 | V22: 0.038003581 | W22: 0.036546241 | X22: 0.035088902 | Y22: 0.033631562 | Z22: 0.03368361 | AA22: 0.033735658 | AB22: 0.033787705 | AC22: 0.033839753 | AD22: 0.033891801 | AE22: 0.033943849 | AF22: 0.033995897 | AG22: 0.034047945 | AH22: 0.034099992 | AI22: 0.03415204 | AJ22: 0.034204088 | AK22: 0.034256136 | AL22: 0.034308184 | AM22: 0.034360232 | AN22: 0.03441228 | AO22: 0.034464327 | AP22: 0.034516375 | AQ22: 0.034568423 | AR22: 0.034620471 | AS22: 0.034672519 | AT22: 0.034672519 | AU22: 0.034672519 | AV22: 0.034672519 | AW22: 0.034672519 | AX22: 0.034672519 | AY22: 0.034672519 | AZ22: 0.034672519 | BA22: 0.034672519 | BB22: 0.034672519 | BC22: 0.034672519 | BD22: 0.034672519 | BE22: 0.034672519 | BF22: 0.034672519 | BG22: 0.034672519 | BH22: 0.034672519 | BI22: 0.034672519 | BJ22: 0.034672519 | BK22: 0.034672519 | BL22: 0.034672519 | BM22: 0.034507701
C24: Etapa 3: Separación en el sitio de disposición final
C25: OSS_INORG | D25: Separación de residuos inorgánicos en sitio de disposición final | E25: 0.024154045 | F25: 0.025147903 | G25: 0.025940634 | H25: 0.028244366 | I25: 0.027714 | J25: 0.02772 | K25: 0.027354 | L25: 0.038622 | M25: 0.0402084 | N25: 0.037584 | O25: 0.0382752 | P25: 0.0385392 | Q25: 0.04021848 | R25: 0.0423756 | S25: 0.0423756 | T25: =$H$90+$H$89*T1 -> 0.04091826 | U25: =$H$90+$H$89*U1 -> 0.039460921 | V25: =$H$90+$H$89*V1 -> 0.038003581 | W25: =$H$90+$H$89*W1 -> 0.036546241 | X25: =$H$90+$H$89*X1 -> 0.035088902 | Y25: =AVERAGE(E25:S25) -> 0.033631562 | Z25: =$I$90+$I$89*Z1 -> 0.03368361 | AA25: =$I$90+$I$89*AA1 -> 0.033735658 | AB25: =$I$90+$I$89*AB1 -> 0.033787705 | AC25: =$I$90+$I$89*AC1 -> 0.033839753 | AD25: =$I$90+$I$89*AD1 -> 0.033891801 | AE25: =$I$90+$I$89*AE1 -> 0.033943849 | AF25: =$I$90+$I$89*AF1 -> 0.033995897 | AG25: =$I$90+$I$89*AG1 -> 0.034047945 | ... AR25: =$I$90+$I$89*AR1 -> 0.034620471 | AS25: =AVERAGE(E25:Y25) -> 0.034672519 | AT25: 0.034672519 | AU25: 0.034672519 | AV25: 0.034672519 | AW25: 0.034672519 | AX25: 0.034672519 | AY25: 0.034672519 | AZ25: 0.034672519 | BA25: 0.034672519 | BB25: 0.034672519 | BC25: 0.034672519 | BD25: 0.034672519 | BE25: 0.034672519 | BF25: 0.034672519 | BG25: 0.034672519 | BH25: 0.034672519 | BI25: 0.034672519 | BJ25: 0.034672519 | BK25: 0.034672519 | BL25: 0.034672519 | BM25: =AVERAGE(E25:BL25) -> 0.034507701
